Workbook

Sheet Assumptions
A1: TITAN COMPANY LIMITED — DCF MODEL | ASSUMPTIONS
A2: Assumption | C2: FY25E | D2: FY26E | E2: FY27E
A3: A. Revenue Growth Assumptions
A4: Watches & Wearables — revenue growth | C4: 0.1 | D4: 0.1 | E4: 0.09
A5: Jewellery — revenue growth | C5: 0.15 | D5: 0.14 | E5: 0.13
A6: Eyecare — revenue growth | C6: 0.12 | D6: 0.12 | E6: 0.11
A7: Others — revenue growth | C7: 0.18 | D7: 0.16 | E7: 0.14
A8: Corporate / Other income — growth | C8: 0.1 | D8: 0.1 | E8: 0.1
A10: B. EBIT Margin Assumptions (Segment EBIT ÷ Segment Revenue)
A11: Watches & Wearables — EBIT margin | C11: 0.1 | D11: 0.105 | E11: 0.108
A12: Jewellery — EBIT margin | C12: 0.106 | D12: 0.11 | E12: 0.114
A13: Eyecare — EBIT margin | C13: 0.11 | D13: 0.12 | E13: 0.13
A14: Others — EBIT margin | C14: 0.01 | D14: 0.02 | E14: 0.03
A15: Corporate unallocated costs (₹ Cr, negative) | C15: -55 | D15: -60 | E15: -65
A17: C. Below-the-line & Balance Sheet Assumptions
A18: Finance costs (₹ Cr) | C18: 580 | D18: 560 | E18: 540
A19: Effective tax rate | C19: 0.244 | D19: 0.244 | E19: 0.244
A20: D&A (₹ Cr) — held constant then grown | C20: 680 | D20: 750 | E20: 830
A21: Capex (₹ Cr) | C21: 780 | D21: 850 | E21: 920
A23: Source: Titan Company FY24 Annual Report (Consolidated) — Segment data from Note 27. Assumptions by analyst.

Sheet IS
A1: TITAN COMPANY LIMITED — CONSOLIDATED INCOME STATEMENT (₹ Crore)
A2: Particulars | C2: FY21A | D2: FY22A | E2: FY23A | F2: FY24A | G2: FY25E | H2: FY26E | I2: FY27E
A3: SEGMENT REVENUE incl. other income (₹ Crore)
A4: Watches & Wearables | C4: 1587 | D4: 2317 | E4: 3310 | F4: 3930 | G4: =F4*(1+Assumptions!C4) -> 4323 | H4: =G4*(1+Assumptions!D4) -> 4755.3 | I4: =H4*(1+Assumptions!E4) -> 5183.277
A5: Jewellery | C5: 19320 | D5: 25523 | E5: 35914 | F5: 45524 | G5: =F5*(1+Assumptions!C5) -> 52352.6 | H5: =G5*(1+Assumptions!D5) -> 59681.964 | I5: =H5*(1+Assumptions!E5) -> 67440.619
A6: Eyecare | C6: 375 | D6: 517 | E6: 689 | F6: 726 | G6: =F6*(1+Assumptions!C6) -> 813.12 | H6: =G6*(1+Assumptions!D6) -> 910.6944 | I6: =H6*(1+Assumptions!E6) -> 1010.8708
A7: Others (Taneira, SKINN, Aerospace etc.) | C7: 457 | D7: 545 | E7: 805 | F7: 1138 | G7: =F7*(1+Assumptions!C7) -> 1342.84 | H7: =G7*(1+Assumptions!D7) -> 1557.6944 | I7: =H7*(1+Assumptions!E7) -> 1775.7716
A8: Corporate & unallocated income | C8: 91 | D8: 131 | E8: 165 | F8: 299 | G8: =F8*(1+Assumptions!C8) -> 328.9 | H8: =G8*(1+Assumptions!D8) -> 361.79 | I8: =H8*(1+Assumptions!E8) -> 397.969
A10: TOTAL REVENUE (incl. other income) | C10: =SUM(C4:C8) -> 21830 | D10: =SUM(D4:D8) -> 29033 | E10: =SUM(E4:E8) -> 40883 | F10: =SUM(F4:F8) -> 51617 | G10: =SUM(G4:G8) -> 59160.46 | H10: =SUM(H4:H8) -> 67267.443 | I10: =SUM(I4:I8) -> 75808.508
A11: Revenue growth YoY % | D11: =IFERROR((D10-C10)/C10,"-") -> 0.32995877 | E11: =IFERROR((E10-D10)/D10,"-") -> 0.40815624 | F11: =IFERROR((F10-E10)/E10,"-") -> 0.26255412 | G11: =IFERROR((G10-F10)/F10,"-") -> 0.14614294 | H11: =IFERROR((H10-G10)/G10,"-") -> 0.1370338 | I11: =IFERROR((I10-H10)/H10,"-") -> 0.12697175
A13: SEGMENT EBIT (₹ Crore) — before exceptional items [Note 27c]
A14: Watches & Wearables — EBIT | C14: -132 | D14: 100 | E14: 408 | F14: 393 | G14: =G4*Assumptions!C11 -> 432.3 | H14: =H4*Assumptions!D11 -> 499.3065 | I14: =I4*Assumptions!E11 -> 559.79392
A15: Jewellery — EBIT | C15: 1701 | D15: 3068 | E15: 4387 | F15: 4812 | G15: =G5*Assumptions!C12 -> 5549.3756 | H15: =H5*Assumptions!D12 -> 6565.016 | I15: =I5*Assumptions!E12 -> 7688.2306
A16: Eyecare — EBIT | C16: 23 | D16: 56 | E16: 98 | F16: 80 | G16: =G6*Assumptions!C13 -> 89.4432 | H16: =H6*Assumptions!D13 -> 109.28333 | I16: =I6*Assumptions!E13 -> 131.4132
A17: Others — EBIT | C17: -5 | D17: -10 | E17: -47 | F17: 5 | G17: =G7*Assumptions!C14 -> 13.4284 | H17: =H7*Assumptions!D14 -> 31.153888 | I17: =I7*Assumptions!E14 -> 53.273148
A18: Corporate (unallocated) | C18: -57 | D18: -38 | E18: -100 | F18: -48 | G18: =Assumptions!C15 -> -55 | H18: =Assumptions!D15 -> -60 | I18: =Assumptions!E15 -> -65
A20: TOTAL EBIT (Segment profit before finance costs) | C20: =SUM(C14:C18) -> 1530 | D20: =SUM(D14:D18) -> 3176 | E20: =SUM(E14:E18) -> 4746 | F20: =SUM(F14:F18) -> 5242 | G20: =SUM(G14:G18) -> 6029.5472 | H20: =SUM(H14:H18) -> 7144.7598 | I20: =SUM(I14:I18) -> 8367.7109
A21: EBIT margin % | C21: =IFERROR(C20/C10,"-") -> 0.070087036 | D21: =IFERROR(D20/D10,"-") -> 0.10939276 | E21: =IFERROR(E20/E10,"-") -> 0.11608737 | F21: =IFERROR(F20/F10,"-") -> 0.10155569 | G21: =IFERROR(G20/G10,"-") -> 0.10191853 | H21: =IFERROR(H20/H10,"-") -> 0.10621423 | I21: =IFERROR(I20/I10,"-") -> 0.11037958
A23: EBITDA (₹ Crore) — EBIT + D&A
A24: Depreciation & Amortisation (D&A) | C24: 375 | D24: 399 | E24: 441 | F24: 584 | G24: =Assumptions!C20 -> 680 | H24: =Assumptions!D20 -> 750 | I24: =Assumptions!E20 -> 830
A25: EBITDA (EBIT + D&A) | C25: =C20+C24 -> 1905 | D25: =D20+D24 -> 3575 | E25: =E20+E24 -> 5187 | F25: =F20+F24 -> 5826 | G25: =G20+G24 -> 6709.5472 | H25: =H20+H24 -> 7894.7598 | I25: =I20+I24 -> 9197.7109
A26: EBITDA margin % | C26: =IFERROR(C25/C10,"-") -> 0.087265231 | D26: =IFERROR(D25/D10,"-") -> 0.12313574 | E26: =IFERROR(E25/E10,"-") -> 0.12687425 | F26: =IFERROR(F25/F10,"-") -> 0.11286979 | G26: =IFERROR(G25/G10,"-") -> 0.11341269 | H26: =IFERROR(H25/H10,"-") -> 0.11736376 | I26: =IFERROR(I25/I10,"-") -> 0.12132821
A28: BELOW THE LINE (₹ Crore)
A29: Finance costs (deducted below) | C29: 203 | D29: 218 | E29: 300 | F29: 619 | G29: =Assumptions!C18 -> 580 | H29: =Assumptions!D18 -> 560 | I29: =Assumptions!E18 -> 540
A31: PROFIT BEFORE TAX (EBIT − Finance costs) | C31: =C20-C29 -> 1327 | D31: =D20-D29 -> 2958 | E31: =E20-E29 -> 4446 | F31: =F20-F29 -> 4623 | G31: =G20-G29 -> 5449.5472 | H31: =H20-H29 -> 6584.7598 | I31: =I20-I29 -> 7827.7109
A33: Tax expense | C33: 353 | D33: 706 | E33: 1173 | F33: 1127 | G33: =IFERROR(G31*Assumptions!C19,0) -> 1329.6895 | H33: =IFERROR(H31*Assumptions!D19,0) -> 1606.6814 | I33: =IFERROR(I31*Assumptions!E19,0) -> 1909.9615
A35: PROFIT AFTER TAX (PAT = PBT − Tax) | C35: =C31-C33 -> 974 | D35: =D31-D33 -> 2252 | E35: =E31-E33 -> 3273 | F35: =F31-F33 -> 3496 | G35: =G31-G33 -> 4119.8577 | H35: =H31-H33 -> 4978.0784 | I35: =I31-I33 -> 5917.7494
A37: KEY METRICS
A38: PAT margin % | C38: =IFERROR(C35/C10,"-") -> 0.044617499 | D38: =IFERROR(D35/D10,"-") -> 0.077566907 | E38: =IFERROR(E35/E10,"-") -> 0.080057726 | F38: =IFERROR(F35/F10,"-") -> 0.067729624 | G38: =IFERROR(G35/G10,"-") -> 0.069638703 | H38: =IFERROR(H35/H10,"-") -> 0.074004276 | I38: =IFERROR(I35/I10,"-") -> 0.078061811
A39: Effective tax rate % | C39: =IFERROR(C33/C31,"-") -> 0.26601356 | D39: =IFERROR(D33/D31,"-") -> 0.23867478 | E39: =IFERROR(E33/E31,"-") -> 0.26383266 | F39: =IFERROR(F33/F31,"-") -> 0.24378109 | G39: =IFERROR(G33/G31,"-") -> 0.244 | H39: =IFERROR(H33/H31,"-") -> 0.244 | I39: =IFERROR(I33/I31,"-") -> 0.244
A40: Jewellery EBIT margin % | C40: =IFERROR(C15/C5,"-") -> 0.088043478 | D40: =IFERROR(D15/D5,"-") -> 0.12020531 | E40: =IFERROR(E15/E5,"-") -> 0.12215292 | F40: =IFERROR(F15/F5,"-") -> 0.10570249 | G40: =IFERROR(G15/G5,"-") -> 0.106 | H40: =IFERROR(H15/H5,"-") -> 0.11 | I40: =IFERROR(I15/I5,"-") -> 0.114
A41: Watches EBIT margin % | C41: =IFERROR(C14/C4,"-") -> -0.083175803 | D41: =IFERROR(D14/D4,"-") -> 0.043159258 | E41: =IFERROR(E14/E4,"-") -> 0.12326284 | F41: =IFERROR(F14/F4,"-") -> 0.1 | G41: =IFERROR(G14/G4,"-") -> 0.1 | H41: =IFERROR(H14/H4,"-") -> 0.105 | I41: =IFERROR(I14/I4,"-") -> 0.108
A43: Sources: FY24 & FY23 — Titan Annual Report 2023-24 (Consolidated P&L + Note 27). FY22 & FY21 — Titan Annual Report 2021-22 (Consolidated P&L + Note 27, Section c — before exceptional items). Blue = hardcoded input | Black = formula | Green = cross-sheet link

Sheet BS
A1: TITAN COMPANY — CONSOLIDATED BALANCE SHEET (₹ Crore)
A2: Particulars | C2: FY23A | D2: FY24A | E2: FY25E | F2: FY26E | G2: FY27E
A3: NON-CURRENT ASSETS
A4: Property, plant & equipment (PP&E) | C4: 1343 | D4: 1737 | E4: =D4+Assumptions!C21-Assumptions!C20 -> 1837 | F4: =E4+Assumptions!D21-Assumptions!D20 -> 1937 | G4: =F4+Assumptions!E21-Assumptions!E20 -> 2027
A5: Right-of-use assets | C5: 1285 | D5: 1543 | E5: =D5 -> 1543 | F5: =E5 -> 1543 | G5: =F5 -> 1543
A6: Goodwill & other intangibles | C6: 369 | D6: 428 | E6: =D6 -> 428 | F6: =E6 -> 428 | G6: =F6 -> 428
A7: Other non-current assets (fin investments, DTA, loans etc.) | C7: 1619 | D7: 2234 | E7: =D7*1.05 -> 2345.7 | F7: =E7*1.05 -> 2462.985 | G7: =F7*1.05 -> 2586.1343
A8: TOTAL NON-CURRENT ASSETS | C8: =SUM(C4:C7) -> 4616 | D8: =SUM(D4:D7) -> 5942 | E8: =SUM(E4:E7) -> 6153.7 | F8: =SUM(F4:F7) -> 6370.985 | G8: =SUM(G4:G7) -> 6584.1343
A10: CURRENT ASSETS
A11: Inventories | C11: 16584 | D11: 19051 | E11: =D11*(IS!G10/IS!F10) -> 21835.169 | F11: =E11*(IS!H10/IS!G10) -> 24827.325 | G11: =F11*(IS!I10/IS!H10) -> 27979.694
A12: Trade receivables | C12: 674 | D12: 1018 | E12: =D12*(IS!G10/IS!F10) -> 1166.7735 | F12: =E12*(IS!H10/IS!G10) -> 1326.6609 | G12: =F12*(IS!I10/IS!H10) -> 1495.1094
A13: Cash & cash equivalents | C13: 232 | D13: 409 | E13: =D13 -> 409 | F13: =E13 -> 409 | G13: =F13 -> 409
A14: Current investments & bank balances | C14: 3275 | D14: 2783 | E14: =D14 -> 2783 | F14: =E14 -> 2783 | G14: =F14 -> 2783
A15: Loans, other financial assets & assets held for sale | C15: 354 | D15: 626 | E15: =D15*(IS!G10/IS!F10) -> 717.48548 | F15: =E15*(IS!H10/IS!G10) -> 815.80524 | G15: =F15*(IS!I10/IS!H10) -> 919.38946
A16: Other current assets | C16: 1288 | D16: 1721 | E16: =D16*(IS!G10/IS!F10) -> 1972.512 | F16: =E16*(IS!H10/IS!G10) -> 2242.8128 | G16: =F16*(IS!I10/IS!H10) -> 2527.5867
A17: TOTAL CURRENT ASSETS | C17: =SUM(C11:C16) -> 22407 | D17: =SUM(D11:D16) -> 25608 | E17: =SUM(E11:E16) -> 28883.94 | F17: =SUM(F11:F16) -> 32404.604 | G17: =SUM(G11:G16) -> 36113.78
A19: TOTAL ASSETS | C19: =C8+C17 -> 27023 | D19: =D8+D17 -> 31550 | E19: =E8+E17 -> 35037.64 | F19: =F8+F17 -> 38775.589 | G19: =G8+G17 -> 42697.914
A21: EQUITY
A22: Equity share capital | C22: 89 | D22: 89 | E22: =D22 -> 89 | F22: =E22 -> 89 | G22: =F22 -> 89
A23: Retained earnings & other equity | C23: 11815 | D23: 9304 | E23: =D23+IS!G35*(1-0.25) -> 12393.893 | F23: =E23+IS!H35*(1-0.25) -> 16127.452 | G23: =F23+IS!I35*(1-0.25) -> 20565.764
A24: TOTAL EQUITY | C24: =C22+C23 -> 11904 | D24: =D22+D23 -> 9393 | E24: =E22+E23 -> 12482.893 | F24: =F22+F23 -> 16216.452 | G24: =G22+G23 -> 20654.764
A26: NON-CURRENT LIABILITIES
A27: Borrowings (long-term) | C27: 0 | D27: 3302 | E27: =D27 -> 3302 | F27: =E27 -> 3302 | G27: =F27 -> 3302
A28: Lease liabilities (non-current) | C28: 1607 | D28: 2032 | E28: =D28 -> 2032 | F28: =E28 -> 2032 | G28: =F28 -> 2032
A29: Other non-current liabilities & provisions | C29: 248 | D29: 294 | E29: =D29 -> 294 | F29: =E29 -> 294 | G29: =F29 -> 294
A30: TOTAL NON-CURRENT LIABILITIES | C30: =SUM(C27:C29) -> 1855 | D30: =SUM(D27:D29) -> 5628 | E30: =SUM(E27:E29) -> 5628 | F30: =SUM(F27:F29) -> 5628 | G30: =SUM(G27:G29) -> 5628
A32: CURRENT LIABILITIES
A33: Borrowings (short-term) | C33: 2195 | D33: 4536 | E33: =D33 -> 4536 | F33: =E33 -> 4536 | G33: =F33 -> 4536
A34: Gold on loan [operational — excluded from net debt] | C34: 5299 | D34: 5341 | E34: =D34*(IS!G10/IS!F10) -> 6121.5494 | F34: =E34*(IS!H10/IS!G10) -> 6960.4086 | G34: =F34*(IS!I10/IS!H10) -> 7844.1839
A35: Trade payables | C35: 1214 | D35: 1410 | E35: =D35*(IS!G10/IS!F10) -> 1616.0615 | F35: =E35*(IS!H10/IS!G10) -> 1837.5166 | G35: =F35*(IS!I10/IS!H10) -> 2070.8293
A36: Other current liabilities & provisions | C36: 3722 | D36: 4255 | E36: =D36*(IS!G10/IS!F10) -> 4876.8382 | F36: =E36*(IS!H10/IS!G10) -> 5545.1299 | G36: =F36*(IS!I10/IS!H10) -> 6249.2047
A37: TOTAL CURRENT LIABILITIES | C37: =SUM(C33:C36) -> 12430 | D37: =SUM(D33:D36) -> 15542 | E37: =SUM(E33:E36) -> 17150.449 | F37: =SUM(F33:F36) -> 18879.055 | G37: =SUM(G33:G36) -> 20700.218
A39: TOTAL EQUITY & LIABILITIES | C39: =C24+C30+C37 -> 26189 | D39: =D24+D30+D37 -> 30563 | E39: =E24+E30+E37 -> 35261.342 | F39: =F24+F30+F37 -> 40723.507 | G39: =G24+G30+G37 -> 46982.982
A41: KEY METRICS
A42: Net Working Capital (Inv + Rec − Payables) | C42: =C11+C12-C35 -> 16044 | D42: =D11+D12-D35 -> 18659 | E42: =E11+E12-E35 -> 21385.881 | F42: =F11+F12-F35 -> 24316.47 | G42: =G11+G12-G35 -> 27403.974
A43: Change in NWC (↑ = cash absorbed by business) | D43: =IFERROR(D42-C42,"-") -> 2615 | E43: =IFERROR(E42-D42,"-") -> 2726.8811 | F43: =IFERROR(F42-E42,"-") -> 2930.5886 | G43: =IFERROR(G42-F42,"-") -> 3087.5047
A44: Net Debt (LT+ST Borrowings − Cash) [gold on loan excluded] | C44: =C27+C33-C13 -> 1963 | D44: =D27+D33-D13 -> 7429 | E44: =E27+E33-E13 -> 7429 | F44: =F27+F33-F13 -> 7429 | G44: =G27+G33-G13 -> 7429
A46: Source: Titan Annual Report 2023-24 — Consolidated Balance Sheet. FY23=comparative year. Blue=hardcoded actuals | Black=formula. Note: Gold on loan (₹5,341 Cr FY24) is an operational liability excluded from net debt calculation.

Sheet CFS
A1: TITAN COMPANY — CONSOLIDATED CASH FLOW STATEMENT (₹ Crore)
A2: Particulars | C2: FY23A | D2: FY24A | E2: FY25E | F2: FY26E | G2: FY27E
A3: A. CASH FROM OPERATIONS (CFO)
A4: Net profit before tax (PBT) | C4: 4447 | D4: 4623 | E4: =IS!G31 -> 5449.5472 | F4: =IS!H31 -> 6584.7598 | G4: =IS!I31 -> 7827.7109
A5: Add: Depreciation & amortisation | C5: 441 | D5: 584 | E5: =Assumptions!C20 -> 680 | F5: =Assumptions!D20 -> 750 | G5: =Assumptions!E20 -> 830
A6: Add: Finance costs (added back; paid separately in CFF) | C6: 300 | D6: 619 | E6: =Assumptions!C18 -> 580 | F6: =Assumptions!D18 -> 560 | G6: =Assumptions!E18 -> 540
A7: Less: Interest & investment income (non-operating) | C7: -249 | D7: -452 | E7: =D7 -> -452 | F7: =E7 -> -452 | G7: =F7 -> -452
A8: Operating profit before working capital changes | C8: 4937 | D8: 5404 | E8: =SUM(E4:E7) -> 6257.5472 | F8: =SUM(F4:F7) -> 7442.7598 | G8: =SUM(G4:G7) -> 8745.7109
A10: Change in inventories (↑ = cash outflow) | C10: -2977 | D10: -2462 | E10: =-(BS!E11-BS!D11) -> -2784.1691 | F10: =-(BS!F11-BS!E11) -> -2992.1563 | G10: =-(BS!G11-BS!F11) -> -3152.3689
A11: Change in trade receivables | C11: -112 | D11: -348 | E11: =-(BS!E12-BS!D12) -> -148.77351 | F11: =-(BS!F12-BS!E12) -> -159.88741 | G11: =-(BS!G12-BS!F12) -> -168.44846
A12: Change in trade payables | C12: -89 | D12: 196 | E12: =BS!E35-BS!D35 -> 206.06154 | F12: =BS!F35-BS!E35 -> 221.45506 | G12: =BS!G35-BS!F35 -> 233.3127
A13: Other working capital changes (net) | C13: 765 | D13: 78 | E13: =D13 -> 78 | F13: =E13 -> 78 | G13: =F13 -> 78
A14: Cash generated from operations before tax | C14: =C8+SUM(C10:C13) -> 2524 | D14: =D8+SUM(D10:D13) -> 2868 | E14: =E8+SUM(E10:E13) -> 3608.6661 | F14: =F8+SUM(F10:F13) -> 4590.1712 | G14: =G8+SUM(G10:G13) -> 5736.2062
A16: Less: Direct taxes paid | C16: -1154 | D16: -1173 | E16: =-Assumptions!C19*IS!G31 -> -1329.6895 | F16: =-Assumptions!D19*IS!H31 -> -1606.6814 | G16: =-Assumptions!E19*IS!I31 -> -1909.9615
A17: NET CASH FROM OPERATIONS (CFO) | C17: =C14+C16 -> 1370 | D17: =D14+D16 -> 1695 | E17: =E14+E16 -> 2278.9766 | F17: =F14+F16 -> 2983.4898 | G17: =G14+G16 -> 3826.2447
A19: B. CASH FROM INVESTING (CFI)
A20: Capex — purchase of PP&E, intangibles & investment property | C20: -432 | D20: -691 | E20: =-Assumptions!C21 -> -780 | F20: =-Assumptions!D21 -> -850 | G20: =-Assumptions!E21 -> -920
A21: Other investing activities (net) | C21: -1379 | D21: 502 | E21: =D21 -> 502 | F21: =E21 -> 502 | G21: =F21 -> 502
A22: NET CASH FROM INVESTING (CFI) | C22: =C20+C21 -> -1811 | D22: =D20+D21 -> -189 | E22: =E20+E21 -> -278 | F22: =F20+F21 -> -348 | G22: =G20+G21 -> -418
A24: C. CASH FROM FINANCING (CFF)
A25: Net borrowings raised / (repaid) | C25: 1677 | D25: 5629 | E25: =0 -> 0 | F25: =0 -> 0 | G25: =0 -> 0
A26: Dividends paid | C26: -666 | D26: -888 | E26: =-IS!G35*0.25 -> -1029.9644 | F26: =-IS!H35*0.25 -> -1244.5196 | G26: =-IS!I35*0.25 -> -1479.4374
A27: Finance costs paid | C27: -300 | D27: -619 | E27: =-Assumptions!C18 -> -580 | F27: =-Assumptions!D18 -> -560 | G27: =-Assumptions!E18 -> -540
A28: Other financing (lease payments, acquisitions etc.) | C28: -254 | D28: -5451 | E28: =-318 -> -318 | F28: =-318 -> -318 | G28: =-318 -> -318
A29: NET CASH FROM FINANCING (CFF) | C29: =SUM(C25:C28) -> 457 | D29: =SUM(D25:D28) -> -1329 | E29: =SUM(E25:E28) -> -1927.9644 | F29: =SUM(F25:F28) -> -2122.5196 | G29: =SUM(G25:G28) -> -2337.4374
A31: FREE CASH FLOW
A32: FREE CASH FLOW = CFO + Capex | C32: =C17+C20 -> 938 | D32: =D17+D20 -> 1004 | E32: =E17+E20 -> 1498.9766 | F32: =F17+F20 -> 2133.4898 | G32: =G17+G20 -> 2906.2447
A34: FCF margin % (FCF ÷ Revenue) | C34: =IFERROR(C32/IS!E10,"-") -> 0.022943522 | D34: =IFERROR(D32/IS!F10,"-") -> 0.019450956 | E34: =IFERROR(E32/IS!G10,"-") -> 0.025337474 | F34: =IFERROR(F32/IS!H10,"-") -> 0.031716529 | G34: =IFERROR(G32/IS!I10,"-") -> 0.038336656
A36: Source: Titan Annual Report 2023-24 — Consolidated CFS. FY24: CFO=1,695 | Capex=691 | FCF=1,004. FY24 CFF includes one-time CaratLane acquisition ₹4,696 Cr — excluded from forecast. Blue=hardcoded | Black=formula.

Sheet DCF
A1: TITAN COMPANY LIMITED — DCF VALUATION (₹ Crore)
A2: Particulars | C2: FY25E | D2: FY26E | E2: FY27E | F2: FY28E | G2: FY29E | I2: DCF Output
A3: STEP 1 — WACC ASSUMPTIONS (change these to run scenarios)
A4: Risk-free rate (India 10Y Gsec yield) | C4: 0.071
A5: Equity risk premium (India ERP) | C5: 0.055
A6: Beta (Titan vs Nifty 50) | C6: 0.85
A7: Cost of equity [= Rf + β×ERP] | C7: =C4+C6*C5 -> 0.11775
A8: Cost of debt (finance costs ÷ total debt) | C8: 0.079
A9: Tax rate (effective) | C9: 0.244
A10: After-tax cost of debt [= Kd×(1−t)] | C10: =C8*(1-C9) -> 0.059724
A11: Weight of equity (mkt cap ÷ (mkt cap + net debt)) | C11: 0.97
A12: Weight of debt | C12: =1-C11 -> 0.03
A13: WACC [= We×Ke + Wd×Kd×(1−t)] | C13: =C11*C7+C12*C10 -> 0.11600922
A14: Terminal growth rate (g) — long-run FCF growth | C14: 0.055
A16: STEP 2 — FREE CASH FLOW FORECAST (₹ Crore)
A17: EBIT (from Income Statement) | C17: =IS!G20 -> 6029.5472 | D17: =IS!H20 -> 7144.7598 | E17: =IS!I20 -> 8367.7109 | F17: =E17*(1+0.12) -> 9371.8362 | G17: =F17*(1+0.11) -> 10402.738
A18: Tax on EBIT [= EBIT × tax rate] | C18: =C17*C9 -> 1471.2095 | D18: =D17*C9 -> 1743.3214 | E18: =E17*C9 -> 2041.7215 | F18: =F17*C9 -> 2286.728 | G18: =G17*C9 -> 2538.2681
A19: NOPAT (Net Operating Profit After Tax = EBIT − Tax) | C19: =C17-C18 -> 4558.3377 | D19: =D17-D18 -> 5401.4384 | E19: =E17-E18 -> 6325.9894 | F19: =F17-F18 -> 7085.1081 | G19: =G17-G18 -> 7864.47
A21: Add: Depreciation & Amortisation | C21: =Assumptions!C20 -> 680 | D21: =Assumptions!D20 -> 750 | E21: =Assumptions!E20 -> 830 | F21: =E21*1.1 -> 913 | G21: =F21*1.1 -> 1004.3
A22: Less: Capex | C22: =-Assumptions!C21 -> -780 | D22: =-Assumptions!D21 -> -850 | E22: =-Assumptions!E21 -> -920 | F22: =E22*1.05 -> -966 | G22: =F22*1.05 -> -1014.3
A23: Less: Change in Net Working Capital (↑NWC = cash absorbed) | C23: =-BS!D43 -> -2615 | D23: =-BS!E43 -> -2726.8811 | E23: =-BS!F43 -> -2930.5886 | F23: =-BS!G43*1.05 -> -3241.8799 | G23: =-BS!G43*1.08 -> -3334.5051
A24: FREE CASH FLOW (NOPAT + D&A + Capex − ΔNWC) | C24: =C19+C21+C22+C23 -> 1843.3377 | D24: =D19+D21+D22+D23 -> 2574.5573 | E24: =E19+E21+E22+E23 -> 3305.4008 | F24: =F19+F21+F22+F23 -> 3790.2282 | G24: =G19+G21+G22+G23 -> 4519.965
A26: STEP 3 — DISCOUNT FACTORS & PRESENT VALUES
A27: Discount period (mid-year convention) | C27: 0.5 | D27: 1.5 | E27: 2.5 | F27: 3.5 | G27: 4.5
A28: Discount factor [= 1÷(1+WACC)ⁿ] | C28: =1/(1+$C$13)^C27 -> 0.94659915 | D28: =1/(1+$C$13)^D27 -> 0.84820011 | E28: =1/(1+$C$13)^E27 -> 0.76002966 | F28: =1/(1+$C$13)^F27 -> 0.68102454 | G28: =1/(1+$C$13)^G27 -> 0.610232
A29: PV of FCF [= FCF × Discount factor] | C29: =C24*C28 -> 1744.9019 | D29: =D24*D28 -> 2183.7398 | E29: =E24*E28 -> 2512.2027 | F29: =F24*F28 -> 2581.2384 | G29: =G24*G28 -> 2758.2273
A31: STEP 4 — TERMINAL VALUE (Gordon Growth Model)
A32: Terminal year FCF (FY29 FCF) | C32: =G24 -> 4519.965
A33: Terminal Value [= FCF₅×(1+g) / (WACC−g)] | C33: =C32*(1+C14)/(C13-C14) -> 78161.351
A34: PV of Terminal Value [= TV ÷ (1+WACC)⁵] | C34: =C33/(1+C13)^5 -> 45149.521
A36: STEP 5 — ENTERPRISE VALUE → EQUITY VALUE → PRICE PER SHARE
A37: Sum of PV of FCFs (FY25E–FY29E) | I37: =SUM(C29:G29) -> 11780.31
A38: PV of Terminal Value | I38: =C34 -> 45149.521
A39: ENTERPRISE VALUE (EV = PV FCFs + PV TV) | I39: =I37+I38 -> 56929.831
A41: Less: Net Debt (FY24A — borrowings minus cash) | I41: =-(BS!D44) -> -7429
A42: Add: Cash & equivalents (already in net debt)
A43: EQUITY VALUE | I43: =I39+I41 -> 49500.831
A45: Shares outstanding (Crore) | I45: 88.7
A46: IMPLIED PRICE PER SHARE (₹) | I46: =I43/I45 -> 558.07024
A48: Current Market Price (CMP) — update manually (₹) | I48: 4450
...

Sheet Scenarios
A1: TITAN — SCENARIO ANALYSIS (Bear / Base / Bull)
A2: Assumption | B2: BEAR | C2: BASE | D2: BULL
A3: REVENUE ASSUMPTIONS
A4: Jewellery revenue CAGR (FY24–FY27) | B4: 0.09 | C4: 0.14 | D4: 0.19
A5: Watches revenue CAGR | B5: 0.07 | C5: 0.1 | D5: 0.13
A6: Eyecare revenue CAGR | B6: 0.08 | C6: 0.12 | D6: 0.15
A8: MARGIN ASSUMPTIONS
A9: Jewellery EBIT margin (FY27E) | B9: 0.095 | C9: 0.114 | D9: 0.13
A10: Group EBITDA margin (FY27E) | B10: 0.1 | C10: 0.122 | D10: 0.135
A12: DCF ASSUMPTIONS
A13: WACC | B13: 0.11 | C13: 0.095 | D13: 0.085
A14: Terminal growth rate (g) | B14: 0.045 | C14: 0.055 | D14: 0.065
A16: OUTPUTS (₹ per share)
A17: Implied Price per Share (₹) | B17: 1950 | C17: =DCF!I46 -> 558.07024 | D17: 4800
A18: CMP (₹) | B18: 3300 | C18: 3300 | D18: 3300
A19: Upside / (Downside) | B19: -0.40909091 | C19: =IFERROR((C17-C18)/C18,0) -> -0.83088781 | D19: 0.45454545
A21: WHAT DRIVES EACH SCENARIO
A22: Bear: Gold price spike crimps jewellery demand; discretionary slowdown; CaratLane integration costs drag margins. Margin compression to <10%.
A23: Base: Steady premiumisation, Tanishq market share gains continue. Margin recovery to FY22 levels by FY27. WACC reflects near-zero-debt structure.
A24: Bull: Accelerated store expansion, studded mix hits 40%+, EyeCare turns meaningfully profitable. Multiple re-rating on quality premium.
A27: SENSITIVITY TABLE — Implied Share Price (₹) by WACC × Terminal Growth Rate
A28: WACC \ TGR → | B28: 0.04 | C28: 0.045 | D28: 0.05 | E28: 0.055 | F28: 0.06 | G28: 0.065 | H28: 0.07
A29: 0.08 | B29: =IFERROR((DCF!C24/(1+0.08)^0.5+DCF!D24/(1+0.08)^1.5+DCF!E24/(1+0.08)^2.5+DCF!F24/(1+0.08)^3.5+DCF!G24/(1+0.08)^4.5+DCF!G24*(1+0.04)/(0.08-0.04)/(1+0.08)^5+BS!D44)/DCF!I45*100,"n/a") -> 113074.54 | C29: =IFERROR((DCF!C24/(1+0.08)^0.5+DCF!D24/(1+0.08)^1.5+DCF!E24/(1+0.08)^2.5+DCF!F24/(1+0.08)^3.5+DCF!G24/(1+0.08)^4.5+DCF!G24*(1+0.045)/(0.08-0.045)/(1+0.08)^5+BS!D44)/DCF!I45*100,"n/a") -> 126451.53 | D29: =IFERROR((DCF!C24/(1+0.08)^0.5+DCF!D24/(1+0.08)^1.5+DCF!E24/(1+0.08)^2.5+DCF!F24/(1+0.08)^3.5+DCF!G24/(1+0.08)^4.5+DCF!G24*(1+0.05)/(0.08-0.05)/(1+0.08)^5+BS!D44)/DCF!I45*100,"n/a") -> 144287.52 | E29: =IFERROR((DCF!C24/(1+0.08)^0.5+DCF!D24/(1+0.08)^1.5+DCF!E24/(1+0.08)^2.5+DCF!F24/(1+0.08)^3.5+DCF!G24/(1+0.08)^4.5+DCF!G24*(1+0.055)/(0.08-0.055)/(1+0.08)^5+BS!D44)/DCF!I45*100,"n/a") -> 169257.9 | F29: =IFERROR((DCF!C24/(1+0.08)^0.5+DCF!D24/(1+0.08)^1.5+DCF!E24/(1+0.08)^2.5+DCF!F24/(1+0.08)^3.5+DCF!G24/(1+0.08)^4.5+DCF!G24*(1+0.06)/(0.08-0.06)/(1+0.08)^5+BS!D44)/DCF!I45*100,"n/a") -> 206713.47 | G29: =IFERROR((DCF!C24/(1+0.08)^0.5+DCF!D24/(1+0.08)^1.5+DCF!E24/(1+0.08)^2.5+DCF!F24/(1+0.08)^3.5+DCF!G24/(1+0.08)^4.5+DCF!G24*(1+0.065)/(0.08-0.065)/(1+0.08)^5+BS!D44)/DCF!I45*100,"n/a") -> 269139.42 | H29: =IFERROR((DCF!C24/(1+0.08)^0.5+DCF!D24/(1+0.08)^1.5+DCF!E24/(1+0.08)^2.5+DCF!F24/(1+0.08)^3.5+DCF!G24/(1+0.08)^4.5+DCF!G24*(1+0.07)/(0.08-0.07)/(1+0.08)^5+BS!D44)/DCF!I45*100,"n/a") -> 393991.33
A30: 0.085 | B30: =IFERROR((DCF!C24/(1+0.085)^0.5+DCF!D24/(1+0.085)^1.5+DCF!E24/(1+0.085)^2.5+DCF!F24/(1+0.085)^3.5+DCF!G24/(1+0.085)^4.5+DCF!G24*(1+0.04)/(0.085-0.04)/(1+0.085)^5+BS!D44)/DCF!I45*100,"n/a") -> 101041.44 | C30: =IFERROR((DCF!C24/(1+0.085)^0.5+DCF!D24/(1+0.085)^1.5+DCF!E24/(1+0.085)^2.5+DCF!F24/(1+0.085)^3.5+DCF!G24/(1+0.085)^4.5+DCF!G24*(1+0.045)/(0.085-0.045)/(1+0.085)^5+BS!D44)/DCF!I45*100,"n/a") -> 111255.3 | D30: =IFERROR((DCF!C24/(1+0.085)^0.5+DCF!D24/(1+0.085)^1.5+DCF!E24/(1+0.085)^2.5+DCF!F24/(1+0.085)^3.5+DCF!G24/(1+0.085)^4.5+DCF!G24*(1+0.05)/(0.085-0.05)/(1+0.085)^5+BS!D44)/DCF!I45*100,"n/a") -> 124387.41 | E30: =IFERROR((DCF!C24/(1+0.085)^0.5+DCF!D24/(1+0.085)^1.5+DCF!E24/(1+0.085)^2.5+DCF!F24/(1+0.085)^3.5+DCF!G24/(1+0.085)^4.5+DCF!G24*(1+0.055)/(0.085-0.055)/(1+0.085)^5+BS!D44)/DCF!I45*100,"n/a") -> 141896.89 | F30: =IFERROR((DCF!C24/(1+0.085)^0.5+DCF!D24/(1+0.085)^1.5+DCF!E24/(1+0.085)^2.5+DCF!F24/(1+0.085)^3.5+DCF!G24/(1+0.085)^4.5+DCF!G24*(1+0.06)/(0.085-0.06)/(1+0.085)^5+BS!D44)/DCF!I45*100,"n/a") -> 166410.16 | G30: =IFERROR((DCF!C24/(1+0.085)^0.5+DCF!D24/(1+0.085)^1.5+DCF!E24/(1+0.085)^2.5+DCF!F24/(1+0.085)^3.5+DCF!G24/(1+0.085)^4.5+DCF!G24*(1+0.065)/(0.085-0.065)/(1+0.085)^5+BS!D44)/DCF!I45*100,"n/a") -> 203180.06 | H30: =IFERROR((DCF!C24/(1+0.085)^0.5+DCF!D24/(1+0.085)^1.5+DCF!E24/(1+0.085)^2.5+DCF!F24/(1+0.085)^3.5+DCF!G24/(1+0.085)^4.5+DCF!G24*(1+0.07)/(0.085-0.07)/(1+0.085)^5+BS!D44)/DCF!I45*100,"n/a") -> 264463.24
A31: 0.09 | B31: =IFERROR((DCF!C24/(1+0.09)^0.5+DCF!D24/(1+0.09)^1.5+DCF!E24/(1+0.09)^2.5+DCF!F24/(1+0.09)^3.5+DCF!G24/(1+0.09)^4.5+DCF!G24*(1+0.04)/(0.09-0.04)/(1+0.09)^5+BS!D44)/DCF!I45*100,"n/a") -> 91426.755 | C31: =IFERROR((DCF!C24/(1+0.09)^0.5+DCF!D24/(1+0.09)^1.5+DCF!E24/(1+0.09)^2.5+DCF!F24/(1+0.09)^3.5+DCF!G24/(1+0.09)^4.5+DCF!G24*(1+0.045)/(0.09-0.045)/(1+0.09)^5+BS!D44)/DCF!I45*100,"n/a") -> 99448.945 | D31: =IFERROR((DCF!C24/(1+0.09)^0.5+DCF!D24/(1+0.09)^1.5+DCF!E24/(1+0.09)^2.5+DCF!F24/(1+0.09)^3.5+DCF!G24/(1+0.09)^4.5+DCF!G24*(1+0.05)/(0.09-0.05)/(1+0.09)^5+BS!D44)/DCF!I45*100,"n/a") -> 109476.68 | E31: =IFERROR((DCF!C24/(1+0.09)^0.5+DCF!D24/(1+0.09)^1.5+DCF!E24/(1+0.09)^2.5+DCF!F24/(1+0.09)^3.5+DCF!G24/(1+0.09)^4.5+DCF!G24*(1+0.055)/(0.09-0.055)/(1+0.09)^5+BS!D44)/DCF!I45*100,"n/a") -> 122369.49 | F31: =IFERROR((DCF!C24/(1+0.09)^0.5+DCF!D24/(1+0.09)^1.5+DCF!E24/(1+0.09)^2.5+DCF!F24/(1+0.09)^3.5+DCF!G24/(1+0.09)^4.5+DCF!G24*(1+0.06)/(0.09-0.06)/(1+0.09)^5+BS!D44)/DCF!I45*100,"n/a") -> 139559.89 | G31: =IFERROR((DCF!C24/(1+0.09)^0.5+DCF!D24/(1+0.09)^1.5+DCF!E24/(1+0.09)^2.5+DCF!F24/(1+0.09)^3.5+DCF!G24/(1+0.09)^4.5+DCF!G24*(1+0.065)/(0.09-0.065)/(1+0.09)^5+BS!D44)/DCF!I45*100,"n/a") -> 163626.46 | H31: =IFERROR((DCF!C24/(1+0.09)^0.5+DCF!D24/(1+0.09)^1.5+DCF!E24/(1+0.09)^2.5+DCF!F24/(1+0.09)^3.5+DCF!G24/(1+0.09)^4.5+DCF!G24*(1+0.07)/(0.09-0.07)/(1+0.09)^5+BS!D44)/DCF!I45*100,"n/a") -> 199726.32
A32: 0.095 | B32: =IFERROR((DCF!C24/(1+0.095)^0.5+DCF!D24/(1+0.095)^1.5+DCF!E24/(1+0.095)^2.5+DCF!F24/(1+0.095)^3.5+DCF!G24/(1+0.095)^4.5+DCF!G24*(1+0.04)/(0.095-0.04)/(1+0.095)^5+BS!D44)/DCF!I45*100,"n/a") -> 83570.542 | C32: =IFERROR((DCF!C24/(1+0.095)^0.5+DCF!D24/(1+0.095)^1.5+DCF!E24/(1+0.095)^2.5+DCF!F24/(1+0.095)^3.5+DCF!G24/(1+0.095)^4.5+DCF!G24*(1+0.045)/(0.095-0.045)/(1+0.095)^5+BS!D44)/DCF!I45*100,"n/a") -> 90015.088 | D32: =IFERROR((DCF!C24/(1+0.095)^0.5+DCF!D24/(1+0.095)^1.5+DCF!E24/(1+0.095)^2.5+DCF!F24/(1+0.095)^3.5+DCF!G24/(1+0.095)^4.5+DCF!G24*(1+0.05)/(0.095-0.05)/(1+0.095)^5+BS!D44)/DCF!I45*100,"n/a") -> 97891.754 | E32: =IFERROR((DCF!C24/(1+0.095)^0.5+DCF!D24/(1+0.095)^1.5+DCF!E24/(1+0.095)^2.5+DCF!F24/(1+0.095)^3.5+DCF!G24/(1+0.095)^4.5+DCF!G24*(1+0.055)/(0.095-0.055)/(1+0.095)^5+BS!D44)/DCF!I45*100,"n/a") -> 107737.59 | F32: =IFERROR((DCF!C24/(1+0.095)^0.5+DCF!D24/(1+0.095)^1.5+DCF!E24/(1+0.095)^2.5+DCF!F24/(1+0.095)^3.5+DCF!G24/(1+0.095)^4.5+DCF!G24*(1+0.06)/(0.095-0.06)/(1+0.095)^5+BS!D44)/DCF!I45*100,"n/a") -> 120396.52 | G32: =IFERROR((DCF!C24/(1+0.095)^0.5+DCF!D24/(1+0.095)^1.5+DCF!E24/(1+0.095)^2.5+DCF!F24/(1+0.095)^3.5+DCF!G24/(1+0.095)^4.5+DCF!G24*(1+0.065)/(0.095-0.065)/(1+0.095)^5+BS!D44)/DCF!I45*100,"n/a") -> 137275.09 | H32: =IFERROR((DCF!C24/(1+0.095)^0.5+DCF!D24/(1+0.095)^1.5+DCF!E24/(1+0.095)^2.5+DCF!F24/(1+0.095)^3.5+DCF!G24/(1+0.095)^4.5+DCF!G24*(1+0.07)/(0.095-0.07)/(1+0.095)^5+BS!D44)/DCF!I45*100,"n/a") -> 160905.09
A33: 0.1 | B33: =IFERROR((DCF!C24/(1+0.1)^0.5+DCF!D24/(1+0.1)^1.5+DCF!E24/(1+0.1)^2.5+DCF!F24/(1+0.1)^3.5+DCF!G24/(1+0.1)^4.5+DCF!G24*(1+0.04)/(0.1-0.04)/(1+0.1)^5+BS!D44)/DCF!I45*100,"n/a") -> 77032.858 | C33: =IFERROR((DCF!C24/(1+0.1)^0.5+DCF!D24/(1+0.1)^1.5+DCF!E24/(1+0.1)^2.5+DCF!F24/(1+0.1)^3.5+DCF!G24/(1+0.1)^4.5+DCF!G24*(1+0.045)/(0.1-0.045)/(1+0.1)^5+BS!D44)/DCF!I45*100,"n/a") -> 82306.331 | D33: =IFERROR((DCF!C24/(1+0.1)^0.5+DCF!D24/(1+0.1)^1.5+DCF!E24/(1+0.1)^2.5+DCF!F24/(1+0.1)^3.5+DCF!G24/(1+0.1)^4.5+DCF!G24*(1+0.05)/(0.1-0.05)/(1+0.1)^5+BS!D44)/DCF!I45*100,"n/a") -> 88634.5 | E33: =IFERROR((DCF!C24/(1+0.1)^0.5+DCF!D24/(1+0.1)^1.5+DCF!E24/(1+0.1)^2.5+DCF!F24/(1+0.1)^3.5+DCF!G24/(1+0.1)^4.5+DCF!G24*(1+0.055)/(0.1-0.055)/(1+0.1)^5+BS!D44)/DCF!I45*100,"n/a") -> 96368.928 | F33: =IFERROR((DCF!C24/(1+0.1)^0.5+DCF!D24/(1+0.1)^1.5+DCF!E24/(1+0.1)^2.5+DCF!F24/(1+0.1)^3.5+DCF!G24/(1+0.1)^4.5+DCF!G24*(1+0.06)/(0.1-0.06)/(1+0.1)^5+BS!D44)/DCF!I45*100,"n/a") -> 106036.96 | G33: =IFERROR((DCF!C24/(1+0.1)^0.5+DCF!D24/(1+0.1)^1.5+DCF!E24/(1+0.1)^2.5+DCF!F24/(1+0.1)^3.5+DCF!G24/(1+0.1)^4.5+DCF!G24*(1+0.065)/(0.1-0.065)/(1+0.1)^5+BS!D44)/DCF!I45*100,"n/a") -> 118467.29 | H33: =IFERROR((DCF!C24/(1+0.1)^0.5+DCF!D24/(1+0.1)^1.5+DCF!E24/(1+0.1)^2.5+DCF!F24/(1+0.1)^3.5+DCF!G24/(1+0.1)^4.5+DCF!G24*(1+0.07)/(0.1-0.07)/(1+0.1)^5+BS!D44)/DCF!I45*100,"n/a") -> 135041.07
A34: 0.105 | B34: =IFERROR((DCF!C24/(1+0.105)^0.5+DCF!D24/(1+0.105)^1.5+DCF!E24/(1+0.105)^2.5+DCF!F24/(1+0.105)^3.5+DCF!G24/(1+0.105)^4.5+DCF!G24*(1+0.04)/(0.105-0.04)/(1+0.105)^5+BS!D44)/DCF!I45*100,"n/a") -> 71509.135 | C34: =IFERROR((DCF!C24/(1+0.105)^0.5+DCF!D24/(1+0.105)^1.5+DCF!E24/(1+0.105)^2.5+DCF!F24/(1+0.105)^3.5+DCF!G24/(1+0.105)^4.5+DCF!G24*(1+0.045)/(0.105-0.045)/(1+0.105)^5+BS!D44)/DCF!I45*100,"n/a") -> 75891.088 | D34: =IFERROR((DCF!C24/(1+0.105)^0.5+DCF!D24/(1+0.105)^1.5+DCF!E24/(1+0.105)^2.5+DCF!F24/(1+0.105)^3.5+DCF!G24/(1+0.105)^4.5+DCF!G24*(1+0.05)/(0.105-0.05)/(1+0.105)^5+BS!D44)/DCF!I45*100,"n/a") -> 81069.76 | E34: =IFERROR((DCF!C24/(1+0.105)^0.5+DCF!D24/(1+0.105)^1.5+DCF!E24/(1+0.105)^2.5+DCF!F24/(1+0.105)^3.5+DCF!G24/(1+0.105)^4.5+DCF!G24*(1+0.055)/(0.105-0.055)/(1+0.105)^5+BS!D44)/DCF!I45*100,"n/a") -> 87284.167 | F34: =IFERROR((DCF!C24/(1+0.105)^0.5+DCF!D24/(1+0.105)^1.5+DCF!E24/(1+0.105)^2.5+DCF!F24/(1+0.105)^3.5+DCF!G24/(1+0.105)^4.5+DCF!G24*(1+0.06)/(0.105-0.06)/(1+0.105)^5+BS!D44)/DCF!I45*100,"n/a") -> 94879.552 | G34: =IFERROR((DCF!C24/(1+0.105)^0.5+DCF!D24/(1+0.105)^1.5+DCF!E24/(1+0.105)^2.5+DCF!F24/(1+0.105)^3.5+DCF!G24/(1+0.105)^4.5+DCF!G24*(1+0.065)/(0.105-0.065)/(1+0.105)^5+BS!D44)/DCF!I45*100,"n/a") -> 104373.78 | H34: =IFERROR((DCF!C24/(1+0.105)^0.5+DCF!D24/(1+0.105)^1.5+DCF!E24/(1+0.105)^2.5+DCF!F24/(1+0.105)^3.5+DCF!G24/(1+0.105)^4.5+DCF!G24*(1+0.07)/(0.105-0.07)/(1+0.105)^5+BS!D44)/DCF!I45*100,"n/a") -> 116580.65
A35: 0.11 | B35: =IFERROR((DCF!C24/(1+0.11)^0.5+DCF!D24/(1+0.11)^1.5+DCF!E24/(1+0.11)^2.5+DCF!F24/(1+0.11)^3.5+DCF!G24/(1+0.11)^4.5+DCF!G24*(1+0.04)/(0.11-0.04)/(1+0.11)^5+BS!D44)/DCF!I45*100,"n/a") -> 66781.838 | C35: =IFERROR((DCF!C24/(1+0.11)^0.5+DCF!D24/(1+0.11)^1.5+DCF!E24/(1+0.11)^2.5+DCF!F24/(1+0.11)^3.5+DCF!G24/(1+0.11)^4.5+DCF!G24*(1+0.045)/(0.11-0.045)/(1+0.11)^5+BS!D44)/DCF!I45*100,"n/a") -> 70470.578 | D35: =IFERROR((DCF!C24/(1+0.11)^0.5+DCF!D24/(1+0.11)^1.5+DCF!E24/(1+0.11)^2.5+DCF!F24/(1+0.11)^3.5+DCF!G24/(1+0.11)^4.5+DCF!G24*(1+0.05)/(0.11-0.05)/(1+0.11)^5+BS!D44)/DCF!I45*100,"n/a") -> 74774.109 | E35: =IFERROR((DCF!C24/(1+0.11)^0.5+DCF!D24/(1+0.11)^1.5+DCF!E24/(1+0.11)^2.5+DCF!F24/(1+0.11)^3.5+DCF!G24/(1+0.11)^4.5+DCF!G24*(1+0.055)/(0.11-0.055)/(1+0.11)^5+BS!D44)/DCF!I45*100,"n/a") -> 79860.1 | F35: =IFERROR((DCF!C24/(1+0.11)^0.5+DCF!D24/(1+0.11)^1.5+DCF!E24/(1+0.11)^2.5+DCF!F24/(1+0.11)^3.5+DCF!G24/(1+0.11)^4.5+DCF!G24*(1+0.06)/(0.11-0.06)/(1+0.11)^5+BS!D44)/DCF!I45*100,"n/a") -> 85963.29 | G35: =IFERROR((DCF!C24/(1+0.11)^0.5+DCF!D24/(1+0.11)^1.5+DCF!E24/(1+0.11)^2.5+DCF!F24/(1+0.11)^3.5+DCF!G24/(1+0.11)^4.5+DCF!G24*(1+0.065)/(0.11-0.065)/(1+0.11)^5+BS!D44)/DCF!I45*100,"n/a") -> 93422.743 | H35: =IFERROR((DCF!C24/(1+0.11)^0.5+DCF!D24/(1+0.11)^1.5+DCF!E24/(1+0.11)^2.5+DCF!F24/(1+0.11)^3.5+DCF!G24/(1+0.11)^4.5+DCF!G24*(1+0.07)/(0.11-0.07)/(1+0.11)^5+BS!D44)/DCF!I45*100,"n/a") -> 102747.06
A36: 0.115 | B36: =IFERROR((DCF!C24/(1+0.115)^0.5+DCF!D24/(1+0.115)^1.5+DCF!E24/(1+0.115)^2.5+DCF!F24/(1+0.115)^3.5+DCF!G24/(1+0.115)^4.5+DCF!G24*(1+0.04)/(0.115-0.04)/(1+0.115)^5+BS!D44)/DCF!I45*100,"n/a") -> 62691.447 | C36: =IFERROR((DCF!C24/(1+0.115)^0.5+DCF!D24/(1+0.115)^1.5+DCF!E24/(1+0.115)^2.5+DCF!F24/(1+0.115)^3.5+DCF!G24/(1+0.115)^4.5+DCF!G24*(1+0.045)/(0.115-0.045)/(1+0.115)^5+BS!D44)/DCF!I45*100,"n/a") -> 65831.397 | D36: =IFERROR((DCF!C24/(1+0.115)^0.5+DCF!D24/(1+0.115)^1.5+DCF!E24/(1+0.115)^2.5+DCF!F24/(1+0.115)^3.5+DCF!G24/(1+0.115)^4.5+DCF!G24*(1+0.05)/(0.115-0.05)/(1+0.115)^5+BS!D44)/DCF!I45*100,"n/a") -> 69454.416 | E36: =IFERROR((DCF!C24/(1+0.115)^0.5+DCF!D24/(1+0.115)^1.5+DCF!E24/(1+0.115)^2.5+DCF!F24/(1+0.115)^3.5+DCF!G24/(1+0.115)^4.5+DCF!G24*(1+0.055)/(0.115-0.055)/(1+0.115)^5+BS!D44)/DCF!I45*100,"n/a") -> 73681.271 | F36: =IFERROR((DCF!C24/(1+0.115)^0.5+DCF!D24/(1+0.115)^1.5+DCF!E24/(1+0.115)^2.5+DCF!F24/(1+0.115)^3.5+DCF!G24/(1+0.115)^4.5+DCF!G24*(1+0.06)/(0.115-0.06)/(1+0.115)^5+BS!D44)/DCF!I45*100,"n/a") -> 78676.645 | G36: =IFERROR((DCF!C24/(1+0.115)^0.5+DCF!D24/(1+0.115)^1.5+DCF!E24/(1+0.115)^2.5+DCF!F24/(1+0.115)^3.5+DCF!G24/(1+0.115)^4.5+DCF!G24*(1+0.065)/(0.115-0.065)/(1+0.115)^5+BS!D44)/DCF!I45*100,"n/a") -> 84671.094 | H36: =IFERROR((DCF!C24/(1+0.115)^0.5+DCF!D24/(1+0.115)^1.5+DCF!E24/(1+0.115)^2.5+DCF!F24/(1+0.115)^3.5+DCF!G24/(1+0.115)^4.5+DCF!G24*(1+0.07)/(0.115-0.07)/(1+0.115)^5+BS!D44)/DCF!I45*100,"n/a") -> 91997.644
A38: Note: Green cell = base case (WACC 9.5%, TGR 5.5%). CMP = ₹3,300. Cells above ₹3,300 = implied upside; below = implied downside.

Sheet Dashboard
M1: Year | N1: Revenue | O1: EBITDA% | P1: FCF
B2: TITAN COMPANY LIMITED (NSE: TITAN) — EQUITY RESEARCH DASHBOARD | M2: FY21A | N2: 21830 | O2: 0.087
B3: Independent Equity Research | Analyst: Shivang Koul, Hansraj College | G3: Data Source: Titan Annual Report FY2023-24 (Consolidated) | May 2026 | M3: FY22A | N3: 29033 | O3: 0.123
M4: FY23A | N4: 40883 | O4: 0.127 | P4: 938
M5: FY24A | N5: 51617 | O5: 0.113 | P5: 1004
B6: RATING | D6: DCF FAIR VALUE | F6: MC MEDIAN (P50) | H6: CMP | J6: RECOMMENDATION | M6: FY25E | N6: 59160 | O6: 0.113 | P6: 1843
B7: HOLD | D7: ₹558 / share | F7: ₹1,206 / share | H7: ₹4,450 | J7: HOLD — <₹3,800 | M7: FY26E | N7: 67267 | O7: 0.117 | P7: 2575
M8: FY27E | N8: 75809 | O8: 0.121 | P8: 3305
B11: FINANCIAL SUMMARY (₹ Crore) | H11: SCENARIO ANALYSIS
B12: Metric | C12: FY22A | D12: FY23A | E12: FY24A | F12: FY27E | I12: BEAR | J12: BASE | K12: BULL
B13: Revenue | C13: 29,033 | D13: 40,883 | E13: 51,617 | F13: ~75,800E | H13: Rev CAGR | I13: 9% | J13: 14% | K13: 19%
B14: EBITDA | C14: 3,575 | D14: 5,187 | E14: 5,826 | F14: ~9,200E | H14: EBIT Margin | I14: 9.5% | J14: 11.4% | K14: 13.0%
B15: EBITDA Mgn | C15: 12.3% | D15: 12.7% | E15: 11.3% | F15: ~12.1%E | H15: WACC | I15: 11.0% | J15: 9.5% | K15: 8.5%
B16: PAT | C16: 2,252 | D16: 3,273 | E16: 3,496 | F16: ~5,900E | H16: Term. Growth | I16: 4.5% | J16: 5.5% | K16: 6.5%
B17: FCF | C17: — | D17: 938 | E17: 1,004 | F17: ~3,200E | H17: Implied Price | I17: ₹1,950 | J17: ₹558 | K17: ₹4,800
B18: Net Debt | C18: — | D18: — | E18: 7,429 | F18: — | H18: vs CMP | I18: −56% | J18: −87% | K18: +8%
B20: DCF BREAKDOWN | H20: MONTE CARLO DCF (10,000 Simulations)
B21: WACC | E21: 9.5% | H21: Simulations | J21: 10,000
B22: Terminal Growth Rate | E22: 5.5% | H22: P10 (Bear) | J22: 766
B23: Sum PV of FCFs | E23: ₹11,780 Cr | H23: P25 | J23: ₹599
B24: PV Terminal Value | E24: ₹45,150 Cr | H24: P50 Median | J24: 1206
B25: TV as % of EV | E25: 79.3% | H25: P75 | J25: 1544
B26: Enterprise Value | E26: ₹56,930 Cr | H26: P90 (Bull) | J26: 1992
B27: Less: Net Debt | E27: ₹7,429 Cr | H27: Std Deviation | J27: 593
B28: Equity Value | E28: ₹49,501 Cr | H28: P(MV > FV) | J28: 99.7%
B29: Implied Price/Share | E29: ₹558 | H29: Top Driver | J29: Rev CAGR r=-0.55
B51: INVESTMENT THESIS & KEY RISKS
B52: THESIS
B53: Tanishq is gaining organised market share in a ₹6L Cr jewellery market at only 7% penetration — a structural runway a 5-year DCF cannot price. Reverse DCF implies the market expects ~22% FCF CAGR over 10 years, consistent with Titan's historical trajectory. Accumulate on dips below ₹3,800.
B55: KEY RISKS
B56: Gold price volatility compresses jewellery margins | CaratLane integration costs drag FCF through FY26 | At 90× PE, any earnings miss triggers outsized correction | Discretionary demand slowdown risk.
B60: Disclaimer: Independent research for academic purposes. Not investment advice. All data from Titan Company Annual Report FY2023-24 (Consolidated). Monte Carlo: 10,000 iterations, inputs calibrated to historical data.
