Workbook

Sheet Dashboard
B2: TITAN COMPANY LIMITED (NSE: TITAN) — EQUITY RESEARCH DASHBOARD | P2: P10 | Q2: 718
B3: Independent Equity Research · Analyst: Shivang Koul | H3: Valuation: FY25-reanchored DCF · not investment advice | P3: P25 | Q3: 849
P4: Median | Q4: 1005
B5: RATING | D5: DCF FAIR VALUE | F5: MC MEDIAN (P50) | H5: CMP | P5: P75 | Q5: 1185
B6: HOLD | D6: =DCF!B38 | F6: 1005 | H6: =DCF!B39 | P6: P90 | Q6: 1387
B8: DCF VALUATION | F8: MONTE CARLO — 10,000 SIMULATIONS
B9: Fair value / share | D9: =DCF!B38 | F9: Valid trials | H9: 10000 | P9: DCF FV | Q9: 1017
B10: Current price (CMP) | D10: =DCF!B39 | F10: Median fair value (P50) | H10: 1005 | P10: MC median | Q10: 1005
B11: Upside / (downside) | D11: =DCF!B40 | F11: Mean fair value | H11: 1034 | P11: MC P10 | Q11: 718
B12: WACC | D12: =DCF!B14 | F12: P10 — bear | H12: 718 | P12: MC P90 | Q12: 1387
B13: Terminal growth | D13: =DCF!B15 | F13: P25 | H13: 849 | P13: CMP | Q13: 4363
B14: Sum PV of FCFF | D14: =DCF!B30 | F14: P75 | H14: 1185
B15: PV of terminal value | D15: =DCF!B33 | F15: P90 — bull | H15: 1387
B16: Terminal value % of EV | D16: =DCF!B41 | F16: P(fair value < CMP) | H16: 1
B17: Enterprise value | D17: =DCF!B34 | F17: 80% confidence interval | H17: ="₹"&TEXT(H12,"#,##0")&" – ₹"&TEXT(H15,"#,##0")
B18: Equity value | D18: =DCF!B36 | F18: MC median vs CMP | H18: =H10/DCF!B39-1
B19: Implied perp. growth (rev-DCF) | D19: =DCF!B45 | F19: MC median vs deterministic | H19: =H10/DCF!B38-1
B21: FINANCIAL SUMMARY (₹ Cr) | F21: KEY SENSITIVITY DRIVERS (rank corr.)
B22: Metric | C22: FY24A | D22: FY25A | E22: FY27E | F22: EBITDA margin | G22: 0.607
B23: Revenue | C23: =IS!E7 | D23: =IS!F7 | E23: =IS!H7 | F23: WACC | G23: -0.557
B24: EBITDA | C24: =IS!E11 | D24: =IS!F11 | E24: =IS!H11 | F24: Terminal growth | G24: 0.339
B25: EBITDA margin | C25: =IS!E11/IS!E7 | D25: =IS!F11/IS!F7 | E25: =IS!H11/IS!H7 | F25: Revenue growth | G25: 0.277
B26: PAT | C26: =IS!E17 | D26: =IS!F17 | E26: =IS!H17 | F26: Capex % | G26: -0.215
F27: Inventory days | G27: -0.113
F28: Tax rate | G28: -0.08
F29: D&A % | G29: 0.029
B31: CONCLUSION
B32: HOLD — a superb business priced for perfection. Deterministic FV ₹1,017 and Monte Carlo median ₹1,005 both sit ~77% below CMP ₹4,363; P(FV<CMP)=100%. No margin of safety.
B34: VISUAL ANALYSIS

Sheet Assumptions
A1: TITAN — ASSUMPTIONS (reanchored to FY25 actuals)
A2: Forecast FY26-FY34. FY26 calibrated to reported FY26 actuals (rev 76,078 / PAT 5,073). Margins reflect real gold-duty compression.
A4: Driver | B4: FY21 | C4: FY22 | D4: FY23 | E4: FY24 | F4: FY25 | G4: FY26 | H4: FY27 | I4: FY28 | J4: FY29 | K4: FY30 | L4: FY31 | M4: FY32 | N4: FY33 | O4: FY34
A5: Core revenue growth % | G5: 0.306 | H5: 0.16 | I5: 0.14 | J5: 0.125 | K5: 0.115 | L5: 0.1 | M5: 0.085 | N5: 0.07 | O5: 0.055
A6: Bullion growth % | G6: 0 | H6: 0 | I6: 0 | J6: 0 | K6: 0 | L6: 0 | M6: 0 | N6: 0 | O6: 0
A7: Operating EBITDA margin % (core) | G7: 0.109 | H7: 0.111 | I7: 0.113 | J7: 0.114 | K7: 0.115 | L7: 0.115 | M7: 0.115 | N7: 0.115 | O7: 0.115
A8: Other income % core | G8: 0.008 | H8: 0.008 | I8: 0.008 | J8: 0.008 | K8: 0.008 | L8: 0.008 | M8: 0.008 | N8: 0.008 | O8: 0.008
A9: D&A % core | G9: 0.012 | H9: 0.012 | I9: 0.012 | J9: 0.012 | K9: 0.012 | L9: 0.012 | M9: 0.012 | N9: 0.012 | O9: 0.012
A10: Capex % core | G10: 0.013 | H10: 0.013 | I10: 0.013 | J10: 0.013 | K10: 0.013 | L10: 0.013 | M10: 0.013 | N10: 0.013 | O10: 0.013
A11: Effective tax rate | G11: 0.255 | H11: 0.255 | I11: 0.255 | J11: 0.255 | K11: 0.255 | L11: 0.255 | M11: 0.255 | N11: 0.255 | O11: 0.255
A12: Dividend payout % | G12: 0.28 | H12: 0.28 | I12: 0.28 | J12: 0.28 | K12: 0.28 | L12: 0.28 | M12: 0.28 | N12: 0.28 | O12: 0.28
A13: Inventory days (core) | G13: 165 | H13: 163 | I13: 161 | J13: 159 | K13: 157 | L13: 156 | M13: 155 | N13: 154 | O13: 153
A14: Receivable days | G14: 7 | H14: 7 | I14: 7 | J14: 7 | K14: 7 | L14: 7 | M14: 7 | N14: 7 | O14: 7
A15: Payable days | G15: 12 | H15: 12 | I15: 12 | J15: 12 | K15: 12 | L15: 12 | M15: 12 | N15: 12 | O15: 12
A16: Gold-on-loan % inventory | G16: 0.28 | H16: 0.28 | I16: 0.28 | J16: 0.28 | K16: 0.28 | L16: 0.28 | M16: 0.28 | N16: 0.28 | O16: 0.28
... A20: Interest rate lease | G20: 0.09 | H20: 0.09 | I20: 0.09 | J20: 0.09 | K20: 0.09 | L20: 0.09 | M20: 0.09 | N20: 0.09 | O20: 0.09

Sheet IS
A1: INCOME STATEMENT (₹ Cr) — Consolidated
A2: FY21-25 ACTUAL (red tint) · FY26-34 forecast. Other income flows to PBT.
B4: FY21 | C4: FY22 | D4: FY23 | E4: FY24 | F4: FY25 | G4: FY26 | H4: FY27 | I4: FY28 | J4: FY29 | K4: FY30 | L4: FY31 | M4: FY32 | N4: FY33 | O4: FY34
A5: Core revenue (ex-bullion) | B5: 21644 | C5: 28799 | D5: 40575 | E5: 46968 | F5: 57332 | G5: =F5*(1+Assumptions!G5) | H5: =G5*(1+Assumptions!H5) | I5: =H5*(1+Assumptions!I5) | J5: =I5*(1+Assumptions!J5) | K5: =J5*(1+Assumptions!K5) | L5: =K5*(1+Assumptions!L5) | M5: =L5*(1+Assumptions!M5) | N5: =M5*(1+Assumptions!N5) | O5: =N5*(1+Assumptions!O5)
A6: Bullion sales | B6: 0 | C6: 0 | D6: 0 | E6: 4116 | F6: 3124 | G6: =F6*(1+Assumptions!G6) | H6: =G6*(1+Assumptions!H6) | I6: =H6*(1+Assumptions!I6) | J6: =I6*(1+Assumptions!J6) | K6: =J6*(1+Assumptions!K6) | L6: =K6*(1+Assumptions!L6) | M6: =L6*(1+Assumptions!M6) | N6: =M6*(1+Assumptions!N6) | O6: =N6*(1+Assumptions!O6)
A7: Revenue from operations | B7: =B5+B6 | C7: =C5+C6 | D7: =D5+D6 | E7: =E5+E6 | F7: =F5+F6 | G7: =G5+G6 | H7: =H5+H6 | I7: =I5+I6 | ... O7: =O5+O6
A8: Other income | B8: 180 | C8: 177 | D8: 308 | E8: 533 | F8: 486 | G8: =G5*Assumptions!G8 | H8: =H5*Assumptions!H8 | I8: =I5*Assumptions!I8 | J8: =J5*Assumptions!J8 | K8: =K5*Assumptions!K8 | L8: =L5*Assumptions!L8 | M8: =M5*Assumptions!M8 | N8: =N5*Assumptions!N8 | O8: =O5*Assumptions!O8
A9: Total income | B9: =B7+B8 | C9: =C7+C8 | D9: =D7+D8 | E9: =E7+E8 | F9: =F7+F8 | G9: =G7+G8 | H9: =H7+H8 | I9: =I7+I8 | ... O9: =O7+O8
A10: Operating expenses (excl D&A, fin) | B10: 19919 | C10: 25455 | D10: 35696 | E10: 45791 | F10: 54761 | G10: =G7-G5*Assumptions!G7 | H10: =H7-H5*Assumptions!H7 | I10: =I7-I5*Assumptions!I7 | J10: =J7-J5*Assumptions!J7 | K10: =K7-K5*Assumptions!K7 | L10: =L7-L5*Assumptions!L7 | M10: =M7-M5*Assumptions!M7 | N10: =N7-N5*Assumptions!N7 | O10: =O7-O5*Assumptions!O7
A11: Operating EBITDA | B11: =B7-B10 | C11: =C7-C10 | D11: =D7-D10 | E11: =E7-E10 | F11: =F7-F10 | G11: =G7-G10 | H11: =H7-H10 | I11: =I7-I10 | ... O11: =O7-O10
A12: Depreciation & amortisation | B12: 375 | C12: 399 | D12: 441 | E12: 584 | F12: 693 | G12: =G5*Assumptions!G9 | H12: =H5*Assumptions!H9 | I12: =I5*Assumptions!I9 | J12: =J5*Assumptions!J9 | K12: =K5*Assumptions!K9 | L12: =L5*Assumptions!L9 | M12: =M5*Assumptions!M9 | N12: =N5*Assumptions!N9 | O12: =O5*Assumptions!O9
A13: EBIT (operating) | B13: =B11-B12 | C13: =C11-C12 | D13: =D11-D12 | E13: =E11-E12 | F13: =F11-F12 | G13: =G11-G12 | H13: =H11-H12 | I13: =I11-I12 | ... O13: =O11-O12
A14: Finance costs | B14: 203 | C14: 218 | D14: 300 | E14: 619 | F14: 953 | G14: =BS!F23*Assumptions!G18+BS!F27*Assumptions!G18+BS!F33*Assumptions!G19+(BS!F24+BS!F28)*Assumptions!G20 | H14: =BS!G23*Assumptions!H18+BS!G27*Assumptions!H18+BS!G33*Assumptions!H19+(BS!G24+BS!G28)*Assumptions!H20 | I14: =BS!H23*Assumptions!I18+BS!H27*Assumptions!I18+BS!H33*Assumptions!I19+(BS!H24+BS!H28)*Assumptions!I20 | J14: =BS!I23*Assumptions!J18+BS!I27*Assumptions!J18+BS!I33*Assumptions!J19+(BS!I24+BS!I28)*Assumptions!J20 | K14: =BS!J23*Assumptions!K18+BS!J27*Assumptions!K18+BS!J33*Assumptions!K19+(BS!J24+BS!J28)*Assumptions!K20 | L14: =BS!K23*Assumptions!L18+BS!K27*Assumptions!L18+BS!K33*Assumptions!L19+(BS!K24+BS!K28)*Assumptions!L20 | M14: =BS!L23*Assumptions!M18+BS!L27*Assumptions!M18+BS!L33*Assumptions!M19+(BS!L24+BS!L28)*Assumptions!M20 | N14: =BS!M23*Assumptions!N18+BS!M27*Assumptions!N18+BS!M33*Assumptions!N19+(BS!M24+BS!M28)*Assumptions!N20 | O14: =BS!N23*Assumptions!O18+BS!N27*Assumptions!O18+BS!N33*Assumptions!O19+(BS!N24+BS!N28)*Assumptions!O20
A15: Profit before tax | B15: =B13+B8-B14 | C15: =C13+C8-C14 | D15: =D13+D8-D14 | E15: =E13+E8-E14 | F15: =F13+F8-F14 | G15: =G13+G8-G14 | H15: =H13+H8-H14 | I15: =I13+I8-I14 | ... O15: =O13+O8-O14
A16: Tax | B16: =B15-974 | C16: =C15-2198 | D16: =D15-3273 | E16: 1127 | F16: 1198 | G16: =G15*Assumptions!G11 | H16: =H15*Assumptions!H11 | I16: =I15*Assumptions!I11 | J16: =J15*Assumptions!J11 | K16: =K15*Assumptions!K11 | L16: =L15*Assumptions!L11 | M16: =M15*Assumptions!M11 | N16: =N15*Assumptions!N11 | O16: =O15*Assumptions!O11
A17: Profit after tax (PAT) | B17: =B15-B16 | C17: =C15-C16 | D17: =D15-D16 | E17: =E15-E16 | F17: =F15-F16 | G17: =G15-G16 | H17: =H15-H16 | I17: =I15-I16 | ... O17: =O15-O16

Sheet BS
A1: BALANCE SHEET (₹ Cr) — Consolidated
A2: FY23-25 actual · FY26-34 forecast. Cash CFS-driven. Balance check = 0 every year.
B4: FY21 | C4: FY22 | D4: FY23 | E4: FY24 | F4: FY25 | G4: FY26 | H4: FY27 | I4: FY28 | J4: FY29 | K4: FY30 | L4: FY31 | M4: FY32 | N4: FY33 | O4: FY34
A5: ASSETS
A6: Property, plant & equipment | D6: 1343 | E6: 1737 | F6: 1854 | G6: =F6+IS!G5*Assumptions!G10-IS!G12 | H6: =G6+IS!H5*Assumptions!H10-IS!H12 | I6: =H6+IS!I5*Assumptions!I10-IS!I12 | J6: =I6+IS!J5*Assumptions!J10-IS!J12 | K6: =J6+IS!K5*Assumptions!K10-IS!K12 | L6: =K6+IS!L5*Assumptions!L10-IS!L12 | M6: =L6+IS!M5*Assumptions!M10-IS!M12 | N6: =M6+IS!N5*Assumptions!N10-IS!N12 | O6: =N6+IS!O5*Assumptions!O10-IS!O12
A7: Right-of-use assets | D7: 1285 | E7: 1543 | F7: 1774 | G7: =F7 | H7: =G7 | I7: =H7 | J7: =I7 | K7: =J7 | L7: =K7 | M7: =L7 | N7: =M7 | O7: =N7
A8: Goodwill | D8: 123 | E8: 123 | F8: 123 | G8: =F8 | H8: =G8 | I8: =H8 | J8: =I8 | K8: =J8 | L8: =K8 | M8: =L8 | N8: =M8 | O8: =N8
A9: Other intangible assets | D9: 246 | E9: 305 | F9: 310 | G9: =F9 | H9: =G9 | I9: =H9 | J9: =I9 | K9: =J9 | L9: =K9 | M9: =L9 | N9: =M9 | O9: =N9
A10: Non-current investments | D10: 351 | E10: 679 | F10: 651 | G10: =F10 | H10: =G10 | I10: =H10 | J10: =I10 | K10: =J10 | L10: =K10 | M10: =L10 | N10: =M10 | O10: =N10
A11: Current investments | D11: 2164 | E11: 1666 | F11: 1337 | G11: =F11 | H11: =G11 | I11: =H11 | J11: =I11 | K11: =J11 | L11: =K11 | M11: =L11 | N11: =M11 | O11: =N11
A12: Inventories | D12: 16584 | E12: 19051 | F12: 28184 | G12: =IS!G5/365*Assumptions!G13 | H12: =IS!H5/365*Assumptions!H13 | I12: =IS!I5/365*Assumptions!I13 | J12: =IS!J5/365*Assumptions!J13 | K12: =IS!K5/365*Assumptions!K13 | L12: =IS!L5/365*Assumptions!L13 | M12: =IS!M5/365*Assumptions!M13 | N12: =IS!N5/365*Assumptions!N13 | O12: =IS!O5/365*Assumptions!O13
A13: Trade receivables | D13: 674 | E13: 1018 | F13: 1068 | G13: =IS!G5/365*Assumptions!G14 | H13: =IS!H5/365*Assumptions!H14 | I13: =IS!I5/365*Assumptions!I14 | J13: =IS!J5/365*Assumptions!J14 | K13: =IS!K5/365*Assumptions!K14 | L13: =IS!L5/365*Assumptions!L14 | M13: =IS!M5/365*Assumptions!M14 | N13: =IS!N5/365*Assumptions!N14 | O13: =IS!O5/365*Assumptions!O14
A14: Cash & cash equivalents | D14: 232 | E14: 409 | F14: 407 | G14: =CFS!G17 | H14: =CFS!H17 | I14: =CFS!I17 | J14: =CFS!J17 | K14: =CFS!K17 | L14: =CFS!L17 | M14: =CFS!M17 | N14: =CFS!N17 | O14: =CFS!O17
A15: Bank balances (other) | D15: 1111 | E15: 1117 | F15: 1177 | G15: =F15 | H15: =G15 | I15: =H15 | J15: =I15 | K15: =J15 | L15: =K15 | M15: =L15 | N15: =M15 | O15: =N15
A16: Loans & other financial assets | D16: 985 | E16: 1468 | F16: 1234 | G16: =F16 | H16: =G16 | I16: =H16 | J16: =I16 | K16: =J16 | L16: =K16 | M16: =L16 | N16: =M16 | O16: =N16
A17: Other assets (catch-all) | D17: 1925 | E17: 2434 | F17: 2528 | G17: =F17 | H17: =G17 | I17: =H17 | J17: =I17 | K17: =J17 | L17: =K17 | M17: =L17 | N17: =M17 | O17: =N17
A18: TOTAL ASSETS | B18: =SUM(B6:B17) | C18: =SUM(C6:C17) | D18: =SUM(D6:D17) | E18: =SUM(E6:E17) | F18: =SUM(F6:F17) | G18: =SUM(G6:G17) | H18: =SUM(H6:H17) | I18: =SUM(I6:I17) | ... O18: =SUM(O6:O17)
A19: EQUITY & LIABILITIES
A20: Equity share capital | D20: 89 | E20: 89 | F20: 89 | G20: =F20 | H20: =G20 | I20: =H20 | J20: =I20 | K20: =J20 | L20: =K20 | M20: =L20 | N20: =M20 | O20: =N20
A21: Other equity (reserves) | D21: 11762 | E21: 9304 | F21: 11535 | G21: =F21+IS!G17*(1-Assumptions!G12) | H21: =G21+IS!H17*(1-Assumptions!H12) | I21: =H21+IS!I17*(1-Assumptions!I12) | J21: =I21+IS!J17*(1-Assumptions!J12) | K21: =J21+IS!K17*(1-Assumptions!K12) | L21: =K21+IS!L17*(1-Assumptions!L12) | M21: =L21+IS!M17*(1-Assumptions!M12) | N21: =M21+IS!N17*(1-Assumptions!N12) | O21: =N21+IS!O17*(1-Assumptions!O12)
A22: Non-controlling interest | D22: 53 | E22: 0 | F22: 16 | G22: =F22 | H22: =G22 | I22: =H22 | J22: =I22 | K22: =J22 | L22: =K22 | M22: =L22 | N22: =M22 | O22: =N22
A23: Non-current borrowings | D23: 0 | E23: 3302 | F23: 595 | G23: =F23 | H23: =G23 | I23: =H23 | J23: =I23 | K23: =J23 | L23: =K23 | M23: =L23 | N23: =M23 | O23: =N23
A24: Lease liabilities — non-current | D24: 1607 | E24: 2032 | F24: 2318 | G24: =F24 | H24: =G24 | I24: =H24 | J24: =I24 | K24: =J24 | L24: =K24 | M24: =L24 | N24: =M24 | O24: =N24
A25: Non-current provisions | D25: 240 | E25: 274 | F25: 299 | G25: =F25 | H25: =G25 | I25: =H25 | J25: =I25 | K25: =J25 | L25: =K25 | M25: =L25 | N25: =M25 | O25: =N25
A26: Deferred tax liability (net) | D26: 3 | E26: 3 | F26: 2 | G26: =F26 | H26: =G26 | I26: =H26 | J26: =I26 | K26: =J26 | L26: =K26 | M26: =L26 | N26: =M26 | O26: =N26
A27: Current borrowings | D27: 2195 | E27: 4536 | F27: 9691 | G27: =F27 | H27: =G27 | I27: =H27 | J27: =I27 | K27: =J27 | L27: =K27 | M27: =L27 | N27: =M27 | O27: =N27
A28: Lease liabilities — current | D28: 266 | E28: 317 | F28: 363 | G28: =F28 | H28: =G28 | I28: =H28 | J28: =I28 | K28: =J28 | L28: =K28 | M28: =L28 | N28: =M28 | O28: =N28
A29: Trade payables | D29: 1214 | E29: 1410 | F29: 1963 | G29: =IS!G5/365*Assumptions!G15 | H29: =IS!H5/365*Assumptions!H15 | I29: =IS!I5/365*Assumptions!I15 | J29: =IS!J5/365*Assumptions!J15 | K29: =IS!K5/365*Assumptions!K15 | L29: =IS!L5/365*Assumptions!L15 | M29: =IS!M5/365*Assumptions!M15 | N29: =IS!N5/365*Assumptions!N15 | O29: =IS!O5/365*Assumptions!O15
A30: Current provisions | D30: 132 | E30: 100 | F30: 155 | G30: =F30 | H30: =G30 | I30: =H30 | J30: =I30 | K30: =J30 | L30: =K30 | M30: =L30 | N30: =M30 | O30: =N30
A31: Current tax liability | D31: 73 | E31: 62 | F31: 40 | G31: =F31 | H31: =G31 | I31: =H31 | J31: =I31 | K31: =J31 | L31: =K31 | M31: =L31 | N31: =M31 | O31: =N31
A32: Other current liabilities (incl advances) | D32: 3517 | E32: 4092 | F32: 4441 | G32: =IS!G5*Assumptions!G17 | H32: =IS!H5*Assumptions!H17 | I32: =IS!I5*Assumptions!I17 | J32: =IS!J5*Assumptions!J17 | K32: =IS!K5*Assumptions!K17 | L32: =IS!L5*Assumptions!L17 | M32: =IS!M5*Assumptions!M17 | N32: =IS!N5*Assumptions!N17 | O32: =IS!O5*Assumptions!O17
A33: Gold on loan | D33: 5299 | E33: 5341 | F33: 7810 | G33: =G12*Assumptions!G16 | H33: =H12*Assumptions!H16 | I33: =I12*Assumptions!I16 | J33: =J12*Assumptions!J16 | K33: =K12*Assumptions!K16 | L33: =L12*Assumptions!L16 | M33: =M12*Assumptions!M16 | N33: =N12*Assumptions!N16 | O33: =O12*Assumptions!O16
A34: Other financial liabilities | D34: 572 | E34: 678 | F34: 1336 | G34: =F34 | H34: =G34 | I34: =H34 | J34: =I34 | K34: =J34 | L34: =K34 | M34: =L34 | N34: =M34 | O34: =N34
A35: Other liabilities (NC)+HFS (catch-all) | D35: 1 | E35: 10 | F35: -6 | G35: =F35 | H35: =G35 | I35: =H35 | J35: =I35 | K35: =J35 | L35: =K35 | M35: =L35 | N35: =M35 | O35: =N35
A36: TOTAL EQUITY & LIAB. | B36: =SUM(B20:B35) | C36: =SUM(C20:C35) | D36: =SUM(D20:D35) | E36: =SUM(E20:E35) | F36: =SUM(F20:F35) | G36: =SUM(G20:G35) | H36: =SUM(H20:H35) | I36: =SUM(I20:I35) | ... O36: =SUM(O20:O35)
A37: BALANCE CHECK (=0) | B37: =B18-B36 | C37: =C18-C36 | D37: =D18-D36 | E37: =E18-E36 | F37: =F18-F36 | G37: =G18-G36 | H37: =H18-H36 | I37: =I18-I36 | ... O37: =O18-O36

Sheet CFS
A1: CASH FLOW STATEMENT (₹ Cr)
A2: FY26-34 forecast (formula). Closing cash → BS cash.
B4: FY21 | C4: FY22 | D4: FY23 | E4: FY24 | F4: FY25 | G4: FY26 | H4: FY27 | I4: FY28 | J4: FY29 | K4: FY30 | L4: FY31 | M4: FY32 | N4: FY33 | O4: FY34
A5: PAT | G5: =IS!G17 | H5: =IS!H17 | I5: =IS!I17 | J5: =IS!J17 | K5: =IS!K17 | L5: =IS!L17 | M5: =IS!M17 | N5: =IS!N17 | O5: =IS!O17
A6: add: D&A | G6: =IS!G12 | H6: =IS!H12 | I6: =IS!I12 | J6: =IS!J12 | K6: =IS!K12 | L6: =IS!L12 | M6: =IS!M12 | N6: =IS!N12 | O6: =IS!O12
A7: less: ∆ Inventories | G7: =-(BS!G12-BS!F12) | H7: =-(BS!H12-BS!G12) | I7: =-(BS!I12-BS!H12) | J7: =-(BS!J12-BS!I12) | K7: =-(BS!K12-BS!J12) | L7: =-(BS!L12-BS!K12) | M7: =-(BS!M12-BS!L12) | N7: =-(BS!N12-BS!M12) | O7: =-(BS!O12-BS!N12)
A8: less: ∆ Receivables | G8: =-(BS!G13-BS!F13) | H8: =-(BS!H13-BS!G13) | I8: =-(BS!I13-BS!H13) | J8: =-(BS!J13-BS!I13) | K8: =-(BS!K13-BS!J13) | L8: =-(BS!L13-BS!K13) | M8: =-(BS!M13-BS!L13) | N8: =-(BS!N13-BS!M13) | O8: =-(BS!O13-BS!N13)
A9: add: ∆ Payables | G9: =(BS!G29-BS!F29) | H9: =(BS!H29-BS!G29) | I9: =(BS!I29-BS!H29) | J9: =(BS!J29-BS!I29) | K9: =(BS!K29-BS!J29) | L9: =(BS!L29-BS!K29) | M9: =(BS!M29-BS!L29) | N9: =(BS!N29-BS!M29) | O9: =(BS!O29-BS!N29)
A10: add: ∆ Other current liab | G10: =(BS!G32-BS!F32) | H10: =(BS!H32-BS!G32) | I10: =(BS!I32-BS!H32) | J10: =(BS!J32-BS!I32) | K10: =(BS!K32-BS!J32) | L10: =(BS!L32-BS!K32) | M10: =(BS!M32-BS!L32) | N10: =(BS!N32-BS!M32) | O10: =(BS!O32-BS!N32)
A11: add: ∆ Gold-on-loan | G11: =(BS!G33-BS!F33) | H11: =(BS!H33-BS!G33) | I11: =(BS!I33-BS!H33) | J11: =(BS!J33-BS!I33) | K11: =(BS!K33-BS!J33) | L11: =(BS!L33-BS!K33) | M11: =(BS!M33-BS!L33) | N11: =(BS!N33-BS!M33) | O11: =(BS!O33-BS!N33)
A12: CFO | G12: =G5+G6+G7+G8+G9+G10+G11 | H12: =H5+H6+H7+H8+H9+H10+H11 | I12: =I5+I6+I7+I8+I9+I10+I11 | J12: =J5+J6+J7+J8+J9+J10+J11 | K12: =K5+K6+K7+K8+K9+K10+K11 | L12: =L5+L6+L7+L8+L9+L10+L11 | M12: =M5+M6+M7+M8+M9+M10+M11 | N12: =N5+N6+N7+N8+N9+N10+N11 | O12: =O5+O6+O7+O8+O9+O10+O11
A13: less: Capex | G13: =-IS!G5*Assumptions!G10 | H13: =-IS!H5*Assumptions!H10 | I13: =-IS!I5*Assumptions!I10 | J13: =-IS!J5*Assumptions!J10 | K13: =-IS!K5*Assumptions!K10 | L13: =-IS!L5*Assumptions!L10 | M13: =-IS!M5*Assumptions!M10 | N13: =-IS!N5*Assumptions!N10 | O13: =-IS!O5*Assumptions!O10
A14: less: Dividends | G14: =-IS!G17*Assumptions!G12 | H14: =-IS!H17*Assumptions!H12 | I14: =-IS!I17*Assumptions!I12 | J14: =-IS!J17*Assumptions!J12 | K14: =-IS!K17*Assumptions!K12 | L14: =-IS!L17*Assumptions!L12 | M14: =-IS!M17*Assumptions!M12 | N14: =-IS!N17*Assumptions!N12 | O14: =-IS!O17*Assumptions!O12
A15: Net change in cash | G15: =G12+G13+G14 | H15: =H12+H13+H14 | I15: =I12+I13+I14 | J15: =J12+J13+J14 | K15: =K12+K13+K14 | L15: =L12+L13+L14 | M15: =M12+M13+M14 | N15: =N12+N13+N14 | O15: =O12+O13+O14
A16: Opening cash | G16: =BS!F14 | H16: =BS!G14 | I16: =BS!H14 | J16: =BS!I14 | K16: =BS!J14 | L16: =BS!K14 | M16: =BS!L14 | N16: =BS!M14 | O16: =BS!N14
A17: Closing cash | G17: =G16+G15 | H17: =H16+H15 | I17: =I16+I15 | J17: =J16+J15 | K17: =K16+K15 | L17: =L16+L15 | M17: =M16+M15 | N17: =N16+N15 | O17: =O16+O15

Sheet DCF
A1: DCF — Two-Stage FCFF (reanchored)
A2: FCFF off statements (FY26-34). WACC build + reverse-DCF. Net debt at FY25.
A4: WACC BUILD
A5: Risk-free rate | B5: 0.07
A6: Equity risk premium | B6: 0.065
A7: Beta | B7: 0.85
A8: Cost of equity | B8: =B5+B7*B6
A9: Pre-tax cost of debt | B9: 0.075
A10: Tax rate | B10: 0.255
A11: After-tax Kd | B11: =B9*(1-B10)
A12: Equity weight | B12: 0.95
A13: Debt weight | B13: 0.05
A14: WACC | B14: =B8*B12+B11*B13
A15: Terminal growth g | B15: 0.055
A17: FREE CASH FLOW TO FIRM
A18: (₹ Cr) | G18: FY26 | H18: FY27 | I18: FY28 | J18: FY29 | K18: FY30 | L18: FY31 | M18: FY32 | N18: FY33 | O18: FY34
A19: EBIT (operating) | G19: =IS!G13 | H19: =IS!H13 | I19: =IS!I13 | J19: =IS!J13 | K19: =IS!K13 | L19: =IS!L13 | M19: =IS!M13 | N19: =IS!N13 | O19: =IS!O13
A20: NOPAT | G20: =G19*(1-Assumptions!G11) | H20: =H19*(1-Assumptions!H11) | I20: =I19*(1-Assumptions!I11) | J20: =J19*(1-Assumptions!J11) | K20: =K19*(1-Assumptions!K11) | L20: =L19*(1-Assumptions!L11) | M20: =M19*(1-Assumptions!M11) | N20: =N19*(1-Assumptions!N11) | O20: =O19*(1-Assumptions!O11)
A21: add: D&A | G21: =IS!G12 | H21: =IS!H12 | I21: =IS!I12 | J21: =IS!J12 | K21: =IS!K12 | L21: =IS!L12 | M21: =IS!M12 | N21: =IS!N12 | O21: =IS!O12
A22: less: Capex | G22: =-IS!G5*Assumptions!G10 | H22: =-IS!H5*Assumptions!H10 | I22: =-IS!I5*Assumptions!I10 | J22: =-IS!J5*Assumptions!J10 | K22: =-IS!K5*Assumptions!K10 | L22: =-IS!L5*Assumptions!L10 | M22: =-IS!M5*Assumptions!M10 | N22: =-IS!N5*Assumptions!N10 | O22: =-IS!O5*Assumptions!O10
A23: less: ∆ NWC | G23: =(CFS!G7+CFS!G8+CFS!G9+CFS!G10+CFS!G11) | H23: =(CFS!H7+CFS!H8+CFS!H9+CFS!H10+CFS!H11) | I23: =(CFS!I7+CFS!I8+CFS!I9+CFS!I10+CFS!I11) | J23: =(CFS!J7+CFS!J8+CFS!J9+CFS!J10+CFS!J11) | K23: =(CFS!K7+CFS!K8+CFS!K9+CFS!K10+CFS!K11) | L23: =(CFS!L7+CFS!L8+CFS!L9+CFS!L10+CFS!L11) | M23: =(CFS!M7+CFS!M8+CFS!M9+CFS!M10+CFS!M11) | N23: =(CFS!N7+CFS!N8+CFS!N9+CFS!N10+CFS!N11) | O23: =(CFS!O7+CFS!O8+CFS!O9+CFS!O10+CFS!O11)
A24: FCFF | G24: =G20+G21+G22+G23 | H24: =H20+H21+H22+H23 | I24: =I20+I21+I22+I23 | J24: =J20+J21+J22+J23 | K24: =K20+K21+K22+K23 | L24: =L20+L21+L22+L23 | M24: =M20+M21+M22+M23 | N24: =N20+N21+N22+N23 | O24: =O20+O21+O22+O23
A25: Discount period | G25: 0.5 | H25: 1.5 | I25: 2.5 | J25: 3.5 | K25: 4.5 | L25: 5.5 | M25: 6.5 | N25: 7.5 | O25: 8.5
A26: Discount factor | G26: =1/(1+$B$14)^G25 | H26: =1/(1+$B$14)^H25 | I26: =1/(1+$B$14)^I25 | J26: =1/(1+$B$14)^J25 | K26: =1/(1+$B$14)^K25 | L26: =1/(1+$B$14)^L25 | M26: =1/(1+$B$14)^M25 | N26: =1/(1+$B$14)^N25 | O26: =1/(1+$B$14)^O25
A27: PV of FCFF | G27: =G24*G26 | H27: =H24*H26 | I27: =I24*I26 | J27: =J24*J26 | K27: =K24*K26 | L27: =L24*L26 | M27: =M24*M26 | N27: =N24*N26 | O27: =O24*O26
A29: VALUATION
A30: Sum PV of FCFF | B30: =SUM(G27:O27)
A31: Terminal FCFF | B31: =O24*(1+$B$15)
A32: Terminal value | B32: =B31/($B$14-$B$15)
A33: PV of terminal value | B33: =B32*O26
A34: Enterprise value | B34: =B30+B33
A35: less: Net debt (FY25, ex-gold) | B35: =BS!F23+BS!F27+BS!F24+BS!F28-BS!F14-BS!F11
A36: Equity value | B36: =B34-B35
A37: Shares (Cr) | B37: =88.8
A38: Fair value / share | B38: =B36/B37
A39: Current price | B39: =4363
A40: Upside/(downside) | B40: =B38/B39-1
A41: TV % of EV | B41: =B33/B34
A43: REVERSE DCF
A44: Implied EV at market | B44: =B39*B37+B35
...
